Workbook

Sheet الملخص
A1: نَسَق — الدراسة المالية لسنة الإطلاق 2027
A2: أُعدت بتاريخ 2026-10-13 بناءً على أرقامك ومسودة التسعير. كل الأرقام هنا معادلات مرتبطة بورقة الافتراضات.
A4: المؤشر | B4: القيمة | C4: ملاحظة
A5: إجمالي تكاليف السنة | B5: ='التدفق الشهري'!N30 | C5: ثابتة + متغيرة، بخطة الاكتساب الحالية
A6: متوسط التكلفة الثابتة الشهرية | B6: ='نقطة التعادل'!B4
A7: التكلفة الثابتة في ديسمبر | B7: ='نقطة التعادل'!B5 | C7: بعد نمو التسويق والاستضافة
A9: هامش المساهمة الشهري للعميل الواحد | B9: ='نقطة التعادل'!B10 | C9: صافي بعد الضريبة ورسوم الدفع والتكلفة المتغيرة
A10: الهامش الإجمالي | B10: ='نقطة التعادل'!B11
A12: عقود سنوية مطلوبة لتغطية تكاليف السنة كاملة | B12: ='نقطة التعادل'!B15 | C12: الرقم الرئيسي: كم عميلًا تحتاج خلال 2027
A13: عملاء نشطون مطلوبون للتعادل الشهري في ديسمبر | B13: ='نقطة التعادل'!B14 | C13: ليتحول النشاط إلى مستدام بعد السنة الأولى
A14: العملاء المخططون في السنة | B14: ='نقطة التعادل'!B16 | C14: عدّل خطة الاكتساب في ورقة الافتراضات
A15: الفجوة بين المخطط والمطلوب | B15: ='نقطة التعادل'!B17 | C15: سالب = نقص في العملاء
A17: الإيراد النقدي المقبوض في السنة | B17: ='التدفق الشهري'!N11
A18: صافي النقد نهاية السنة | B18: ='التدفق الشهري'!N34
A19: رأس المال المطلوب (أعمق نقطة سالبة في النقد) | B19: ='التدفق الشهري'!B38 | C19: المبلغ الذي تحتاج توفيره قبل البداية
A20: الإيراد المؤجل نهاية السنة | B20: ='التدفق الشهري'!B39 | C20: مقبوض لكنه التزام بخدمة في 2028
A22: تكلفة اكتساب العميل (CAC) | B22: ='نقطة التعادل'!B27
A23: فترة استرداد CAC بالأشهر | B23: ='نقطة التعادل'!B29 | C23: الهدف أقل من 12
A26: دليل الألوان
A27: أزرق على أصفر: مدخل تعدّله
A28: أسود: معادلة
A29: أخضر: مرتبط بورقة أخرى
A31: أسئلة تغيّر النتيجة (أجب عليها وعدّل الافتراضات)
A32: 2. متى يبدأ موظف المبيعات فعلًا؟ يناير أم بعد جاهزية المنتج؟ (B9)
A33: 3. هل التسويق ثابت 1,000 أم ينمو؟ وبأي نسبة؟ (B13)
A34: 4. ما المزيج المتوقع للعملاء: حزمة كاملة أم تطبيق واحد؟ (B27–B30)
A35: 5. هل عندك مصاريف أخرى: مكتب، سفر، عمولة مبيعات، رخص SaaS أخرى؟
A36: 6. كم عميلًا تتوقع من موظف المبيعات شهريًا بشكل واقعي؟ (خطة الاكتساب)

Sheet الافتراضات
A1: الافتراضات الأساسية — سنة الإطلاق 2027
A2: الخلايا الزرقاء على خلفية صفراء هي المدخلات التي تعدّلها. كل ما عداها معادلات.
A4: البند | B4: القيمة | C4: المصدر / الملاحظة
A5: تاريخ بداية السنة | B5: 2027-01-01 | C5: حسب طلبك: السنة تبدأ من شهر 1 ميلادي القادم
A6: — التكاليف الثابتة الشهرية (ر.س) —
A7: راتبك الشهري (المؤسس) | B7: 4000 | C7: رقمك
A8: راتب موظف المبيعات | B8: 6000 | C8: رقمك
A9: شهر بداية موظف المبيعات (1 = يناير) | B9: 1 | C9: افتراض: يبدأ من أول شهر. غيّره إذا ستوظفه لاحقًا
A10: نسبة التأمينات الاجتماعية على الرواتب (حصة صاحب العمل) | B10: 0 | C10: قرارك 2026-10-13: بدون تأمينات اجتماعية في السنة الأولى. لو سجّلت لاحقًا فحصة صاحب العمل لموظف سعودي ≈ 11.75٪
A11: أدوات الذكاء الاصطناعي | B11: 2000 | C11: رقمك
A12: التسويق في الشهر الأول | B12: 1000 | C12: رقمك: يبدأ من 1,000
A13: نسبة زيادة التسويق شهريًا | B13: 0.1 | C13: افتراض: زيادة 10٪ كل شهر. ضعها 0 لتثبيت 1,000
A14: الاستضافة — المرحلة الأولى (شهري) | B14: 300 | C14: تقدير: Oracle Cloud منطقة الرياض (me-riyadh-1)، Ampere A1 بـ 4 OCPU و24 GB ≈ 56$ + تخزين 200 GB ونسخ احتياطي ≈ 80$ شهريًا ≈ 300 ر.س. السعر العالمي 0.01$/OCPU-ساعة و0.0015$/GB-ساعة (oracle.com/sa/cloud/price-list)؛ سعر الرياض قد يزيد قليلًا، يُراجع عند التعاقد. Google Cloud ليس له منطقة في الرياض (الدمام فقط)
A15: الاستضافة — المرحلة الثانية (شهري) | B15: 600 | C15: تقدير: مضاعفة الموارد في الرياض إلى 8 OCPU و48 GB مع نسخ احتياطي إلى منطقة جدة. للمقارنة: Google Cloud الدمام e2-standard-4 ≈ 156$ + قرص ونسخ ≈ 200$ ≈ 750 ر.س، لكنه خارج الرياض
A16: عدد العملاء الذي يستدعي المرحلة الثانية | B16: 30 | C16: افتراض: الانتقال عند 30 عميلًا نشطًا
A17: أدوات وبرمجيات (نطاق، بريد، GitHub، أداة دعم) | B17: 300 | C17: افتراض
A18: محاسبة وقانوني ورسوم حكومية (متوسط شهري) | B18: 500 | C18: افتراض: محاسب خارجي + سجل تجاري + منصة فوترة
A19: — التسعير (ر.س، سنوي، شامل الضريبة) —
A20: ضريبة القيمة المضافة | B20: 0.15 | C20: 15٪. الإيراد الصافي = السعر ÷ 1.15
A21: رسوم بوابة الدفع (نسبة من الفاتورة) | B21: 0.025 | C21: افتراض: 2.5٪ + رسم ثابت بسيط
A22: الحزمة الكاملة (3 تطبيقات) — عرض الإطلاق | B22: 5250 | C22: من مسودة التسعير: ادفع 10 أشهر واستخدم 12
A23: المشاريع فقط | B23: 2500 | C23: من مسودة التسعير
A24: المشاريع + الموارد البشرية | B24: 4000 | C24: من مسودة التسعير (2,500 + 1,500)
A25: الموارد البشرية فقط | B25: 1500 | C25: من مسودة التسعير
A26: — مزيج العملاء المتوقع (مجموعه 100٪) —
A27: نسبة عملاء الحزمة الكاملة | B27: 0.4 | C27: افتراض
A28: نسبة عملاء المشاريع فقط | B28: 0.3 | C28: افتراض
A29: نسبة عملاء المشاريع + الموارد البشرية | B29: 0.2 | C29: افتراض
A30: نسبة عملاء الموارد البشرية فقط | B30: 0.1 | C30: افتراض
A31: مجموع النسب (يجب أن يساوي 100٪) | B31: =B27+B28+B29+B30 | C31: تحقق
A32: متوسط قيمة العقد السنوي شامل الضريبة | B32: =B22*B27+B23*B28+B24*B29+B25*B30 | C32: معادلة مرجحة بالمزيج
A33: متوسط قيمة العقد السنوي صافي الضريبة | B33: =B32/(1+B20)
A34: صافي العقد بعد رسوم الدفع | B34: =B33-B32*B21 | C34: رسوم البوابة تُحسب على المبلغ شامل الضريبة
A35: — التكلفة المتغيرة لكل عميل شهريًا (ر.س) —
A36: حوسبة وتخزين ونسخ احتياطي إضافية للعميل | B36: 25 | C36: افتراض: قاعدة بيانات وملفات مستقلة لكل عميل. يُقاس فعليًا بعد أول 3 أشهر
A37: دعم فني: ساعات شهريًا لكل عميل | B37: 0.5 | C37: افتراض: نصف ساعة شهريًا بعد شهر الإعداد
A38: تكلفة ساعة الدعم | B38: 50 | C38: افتراض: وقتك أو وقت موظف المبيعات محسوب بسعر السوق
A39: إجمالي التكلفة المتغيرة لكل عميل شهريًا | B39: =B36+B37*B38
A40: تكلفة إعداد عميل جديد (مرة واحدة) | B40: 200 | C40: افتراض: 4 ساعات إعداد ونقل بيانات × 50 ر.س
A41: — خطة اكتساب العملاء (عملاء جدد كل شهر) —
...

Sheet التدفق الشهري
A1: الإيرادات والتكاليف الشهرية — 2027 (ر.س)
A2: الإيراد النقدي = ما يُقبض فعلًا (دفع سنوي مقدمًا). الإيراد المحاسبي = العقد موزعًا على 12 شهرًا.
A4: البند | B4: يناير 2027 | C4: فبراير 2027 | D4: مارس 2027 | E4: أبريل 2027 | F4: مايو 2027 | G4: يونيو 2027 | H4: يوليو 2027 | I4: أغسطس 2027 | J4: سبتمبر 2027 | K4: أكتوبر 2027 | L4: نوفمبر 2027 | M4: ديسمبر 2027 | N4: إجمالي السنة
A5: رقم الشهر | B5: 1 | C5: 2 | D5: 3 | E5: 4 | F5: 5 | G5: 6 | H5: 7 | I5: 8 | J5: 9 | K5: 10 | L5: 11 | M5: 12
A6: عملاء جدد | B6: =الافتراضات!$B$42 | C6: =الافتراضات!$B$43 | D6: =الافتراضات!$B$44 | E6: =الافتراضات!$B$45 | F6: =الافتراضات!$B$46 | G6: =الافتراضات!$B$47 | H6: =الافتراضات!$B$48 | I6: =الافتراضات!$B$49 | J6: =الافتراضات!$B$50 | K6: =الافتراضات!$B$51 | L6: =الافتراضات!$B$52 | M6: =الافتراضات!$B$53 | N6: =SUM(B6:M6)
A7: عملاء مغادرون | B7: =ROUND(0*الافتراضات!$B$55,0) | C7: =ROUND(B8*الافتراضات!$B$55,0) | D7: =ROUND(C8*الافتراضات!$B$55,0) | E7: =ROUND(D8*الافتراضات!$B$55,0) | F7: =ROUND(E8*الافتراضات!$B$55,0) | G7: =ROUND(F8*الافتراضات!$B$55,0) | H7: =ROUND(G8*الافتراضات!$B$55,0) | I7: =ROUND(H8*الافتراضات!$B$55,0) | J7: =ROUND(I8*الافتراضات!$B$55,0) | ... M7: =ROUND(L8*الافتراضات!$B$55,0) | N7: =SUM(B7:M7)
A8: العملاء النشطون نهاية الشهر | B8: =0+B6-B7 | C8: =B8+C6-C7 | D8: =C8+D6-D7 | E8: =D8+E6-E7 | F8: =E8+F6-F7 | G8: =F8+G6-G7 | H8: =G8+H6-H7 | I8: =H8+I6-I7 | J8: =I8+J6-J7 | ... M8: =L8+M6-M7 | N8: =M8
A10: — الإيرادات —
A11: الإيراد النقدي المقبوض (صافي الضريبة ورسوم الدفع) | B11: =B6*الافتراضات!$B$34 | C11: =C6*الافتراضات!$B$34 | D11: =D6*الافتراضات!$B$34 | E11: =E6*الافتراضات!$B$34 | F11: =F6*الافتراضات!$B$34 | G11: =G6*الافتراضات!$B$34 | H11: =H6*الافتراضات!$B$34 | I11: =I6*الافتراضات!$B$34 | ... M11: =M6*الافتراضات!$B$34 | N11: =SUM(B11:M11)
A12: الإيراد المحاسبي للشهر (العقد ÷ 12) | B12: =B8*الافتراضات!$B$34/12 | C12: =C8*الافتراضات!$B$34/12 | D12: =D8*الافتراضات!$B$34/12 | E12: =E8*الافتراضات!$B$34/12 | F12: =F8*الافتراضات!$B$34/12 | G12: =G8*الافتراضات!$B$34/12 | H12: =H8*الافتراضات!$B$34/12 | I12: =I8*الافتراضات!$B$34/12 | ... M12: =M8*الافتراضات!$B$34/12 | N12: =SUM(B12:M12)
A14: — التكاليف الثابتة —
A15: راتب المؤسس | B15: =الافتراضات!$B$7 | C15: =الافتراضات!$B$7 | D15: =الافتراضات!$B$7 | E15: =الافتراضات!$B$7 | F15: =الافتراضات!$B$7 | G15: =الافتراضات!$B$7 | H15: =الافتراضات!$B$7 | I15: =الافتراضات!$B$7 | ... M15: =الافتراضات!$B$7 | N15: =SUM(B15:M15)
A16: راتب موظف المبيعات | B16: =IF(B5>=الافتراضات!$B$9,الافتراضات!$B$8,0) | C16: =IF(C5>=الافتراضات!$B$9,الافتراضات!$B$8,0) | D16: =IF(D5>=الافتراضات!$B$9,الافتراضات!$B$8,0) | E16: =IF(E5>=الافتراضات!$B$9,الافتراضات!$B$8,0) | F16: =IF(F5>=الافتراضات!$B$9,الافتراضات!$B$8,0) | G16: =IF(G5>=الافتراضات!$B$9,الافتراضات!$B$8,0) | H16: =IF(H5>=الافتراضات!$B$9,الافتراضات!$B$8,0) | I16: =IF(I5>=الافتراضات!$B$9,الافتراضات!$B$8,0) | ... M16: =IF(M5>=الافتراضات!$B$9,الافتراضات!$B$8,0) | N16: =SUM(B16:M16)
A17: التأمينات الاجتماعية (حصة صاحب العمل) | B17: =(B15+B16)*الافتراضات!$B$10 | C17: =(C15+C16)*الافتراضات!$B$10 | D17: =(D15+D16)*الافتراضات!$B$10 | E17: =(E15+E16)*الافتراضات!$B$10 | F17: =(F15+F16)*الافتراضات!$B$10 | G17: =(G15+G16)*الافتراضات!$B$10 | H17: =(H15+H16)*الافتراضات!$B$10 | I17: =(I15+I16)*الافتراضات!$B$10 | ... M17: =(M15+M16)*الافتراضات!$B$10 | N17: =SUM(B17:M17)
A18: أدوات الذكاء الاصطناعي | B18: =الافتراضات!$B$11 | C18: =الافتراضات!$B$11 | D18: =الافتراضات!$B$11 | E18: =الافتراضات!$B$11 | F18: =الافتراضات!$B$11 | G18: =الافتراضات!$B$11 | H18: =الافتراضات!$B$11 | I18: =الافتراضات!$B$11 | ... M18: =الافتراضات!$B$11 | N18: =SUM(B18:M18)
A19: التسويق | B19: =الافتراضات!$B$12 | C19: =B19*(1+الافتراضات!$B$13) | D19: =C19*(1+الافتراضات!$B$13) | E19: =D19*(1+الافتراضات!$B$13) | F19: =E19*(1+الافتراضات!$B$13) | G19: =F19*(1+الافتراضات!$B$13) | H19: =G19*(1+الافتراضات!$B$13) | I19: =H19*(1+الافتراضات!$B$13) | J19: =I19*(1+الافتراضات!$B$13) | ... M19: =L19*(1+الافتراضات!$B$13) | N19: =SUM(B19:M19)
A20: الاستضافة | B20: =IF(B8>=الافتراضات!$B$16,الافتراضات!$B$15,الافتراضات!$B$14) | C20: =IF(C8>=الافتراضات!$B$16,الافتراضات!$B$15,الافتراضات!$B$14) | D20: =IF(D8>=الافتراضات!$B$16,الافتراضات!$B$15,الافتراضات!$B$14) | E20: =IF(E8>=الافتراضات!$B$16,الافتراضات!$B$15,الافتراضات!$B$14) | F20: =IF(F8>=الافتراضات!$B$16,الافتراضات!$B$15,الافتراضات!$B$14) | G20: =IF(G8>=الافتراضات!$B$16,الافتراضات!$B$15,الافتراضات!$B$14) | H20: =IF(H8>=الافتراضات!$B$16,الافتراضات!$B$15,الافتراضات!$B$14) | I20: =IF(I8>=الافتراضات!$B$16,الافتراضات!$B$15,الافتراضات!$B$14) | ... M20: =IF(M8>=الافتراضات!$B$16,الافتراضات!$B$15,الافتراضات!$B$14) | N20: =SUM(B20:M20)
A21: أدوات وبرمجيات | B21: =الافتراضات!$B$17 | C21: =الافتراضات!$B$17 | D21: =الافتراضات!$B$17 | E21: =الافتراضات!$B$17 | F21: =الافتراضات!$B$17 | G21: =الافتراضات!$B$17 | H21: =الافتراضات!$B$17 | I21: =الافتراضات!$B$17 | ... M21: =الافتراضات!$B$17 | N21: =SUM(B21:M21)
A22: محاسبة وقانوني ورسوم | B22: =الافتراضات!$B$18 | C22: =الافتراضات!$B$18 | D22: =الافتراضات!$B$18 | E22: =الافتراضات!$B$18 | F22: =الافتراضات!$B$18 | G22: =الافتراضات!$B$18 | H22: =الافتراضات!$B$18 | I22: =الافتراضات!$B$18 | ... M22: =الافتراضات!$B$18 | N22: =SUM(B22:M22)
A23: إجمالي التكاليف الثابتة | B23: =SUM(B15:B22) | C23: =SUM(C15:C22) | D23: =SUM(D15:D22) | E23: =SUM(E15:E22) | F23: =SUM(F15:F22) | G23: =SUM(G15:G22) | H23: =SUM(H15:H22) | I23: =SUM(I15:I22) | ... M23: =SUM(M15:M22) | N23: =SUM(B23:M23)
A25: — التكاليف المتغيرة —
A26: تشغيل ودعم العملاء النشطين | B26: =B8*الافتراضات!$B$39 | C26: =C8*الافتراضات!$B$39 | D26: =D8*الافتراضات!$B$39 | E26: =E8*الافتراضات!$B$39 | F26: =F8*الافتراضات!$B$39 | G26: =G8*الافتراضات!$B$39 | H26: =H8*الافتراضات!$B$39 | I26: =I8*الافتراضات!$B$39 | ... M26: =M8*الافتراضات!$B$39 | N26: =SUM(B26:M26)
A27: إعداد العملاء الجدد | B27: =B6*الافتراضات!$B$40 | C27: =C6*الافتراضات!$B$40 | D27: =D6*الافتراضات!$B$40 | E27: =E6*الافتراضات!$B$40 | F27: =F6*الافتراضات!$B$40 | G27: =G6*الافتراضات!$B$40 | H27: =H6*الافتراضات!$B$40 | I27: =I6*الافتراضات!$B$40 | ... M27: =M6*الافتراضات!$B$40 | N27: =SUM(B27:M27)
A28: إجمالي التكاليف المتغيرة | B28: =B26+B27 | C28: =C26+C27 | D28: =D26+D27 | E28: =E26+E27 | F28: =F26+F27 | G28: =G26+G27 | H28: =H26+H27 | I28: =I26+I27 | ... M28: =M26+M27 | N28: =SUM(B28:M28)
A30: إجمالي التكاليف | B30: =B23+B28 | C30: =C23+C28 | D30: =D23+D28 | E30: =E23+E28 | F30: =F23+F28 | G30: =G23+G28 | H30: =H23+H28 | I30: =I23+I28 | ... M30: =M23+M28 | N30: =SUM(B30:M30)
A32: — النتيجة —
A33: صافي التدفق النقدي للشهر | B33: =B11-B30 | C33: =C11-C30 | D33: =D11-D30 | E33: =E11-E30 | F33: =F11-F30 | G33: =G11-G30 | H33: =H11-H30 | I33: =I11-I30 | ... M33: =M11-M30 | N33: =SUM(B33:M33)
A34: التدفق النقدي التراكمي | B34: =0+B33 | C34: =B34+C33 | D34: =C34+D33 | E34: =D34+E33 | F34: =E34+F33 | G34: =F34+G33 | H34: =G34+H33 | I34: =H34+I33 | J34: =I34+J33 | ... M34: =L34+M33 | N34: =M34
A35: صافي الربح المحاسبي للشهر | B35: =B12-B30 | C35: =C12-C30 | D35: =D12-D30 | E35: =E12-E30 | F35: =F12-F30 | G35: =G12-G30 | H35: =H12-H30 | I35: =I12-I30 | ... M35: =M12-M30 | N35: =SUM(B35:M35)
A36: الربح المحاسبي التراكمي | B36: =0+B35 | C36: =B36+C35 | D36: =C36+D35 | E36: =D36+E35 | F36: =E36+F35 | G36: =F36+G35 | H36: =G36+H35 | I36: =H36+I35 | J36: =I36+J35 | ... M36: =L36+M35 | N36: =M36
A38: أدنى نقطة في التدفق النقدي التراكمي (رأس المال المطلوب) | B38: =MIN(B34:M34)
A39: الإيراد المؤجل نهاية السنة (مقبوض ولم يُكتسب بعد) | B39: =N11-N12

Sheet نقطة التعادل
A1: نقطة التعادل — كم عميلًا أحتاج؟
A3: المقياس | B3: القيمة | C3: التفسير
A4: متوسط التكلفة الثابتة الشهرية | B4: ='التدفق الشهري'!N23/12 | C4: من ورقة التدفق
A5: التكلفة الثابتة في ديسمبر (مستوى التشغيل الكامل) | B5: ='التدفق الشهري'!M23 | C5: آخر شهر، بعد نمو التسويق والاستضافة
A6: إجمالي تكاليف السنة | B6: ='التدفق الشهري'!N30 | C6: ثابتة + متغيرة
A8: الإيراد الشهري الصافي من العميل الواحد | B8: =الافتراضات!$B$34/12 | C8: بعد الضريبة ورسوم الدفع
A9: التكلفة المتغيرة الشهرية للعميل | B9: =الافتراضات!$B$39
A10: هامش المساهمة الشهري للعميل | B10: =B8-B9 | C10: ما يبقى لتغطية التكاليف الثابتة
A11: الهامش الإجمالي | B11: =IF(B8=0,0,B10/B8) | C11: الهدف الصحي في SaaS: 70٪ فأكثر
A13: عملاء نشطون لتعادل متوسط الشهر (محاسبي) | B13: =IF(B10<=0,0,ROUNDUP(B4/B10,0)) | C13: عدد العملاء النشطين في الوقت نفسه ليغطي الإيراد المحاسبي التكاليف الثابتة
A14: عملاء نشطون لتعادل شهر ديسمبر (محاسبي) | B14: =IF(B10<=0,0,ROUNDUP(B5/B10,0)) | C14: العدد المطلوب عند مستوى التشغيل الكامل
A15: عقود سنوية مقبوضة لتغطية تكاليف السنة كاملة (نقدي) | B15: =IF((الافتراضات!$B$34-B9*12-الافتراضات!$B$40)<=0,0,ROUNDUP(('التدفق الشهري'!N23)/(الافتراضات!$B$34-B9*12-الافتراضات!$B$40),0)) | C15: كم عقدًا سنويًا يجب بيعه خلال السنة حتى يغطي المقبوض كل تكاليف السنة
A16: العملاء المخططون في السنة | B16: =الافتراضات!$B$54 | C16: من خطة الاكتساب
A17: الفجوة (مخطط − مطلوب نقديًا) | B17: =B16-B15 | C17: موجب = الخطة تغطي السنة، سالب = نقص
A19: — حسب نوع العميل: عقود سنوية مطلوبة لتغطية السنة —
A20: لو كل العملاء حزمة كاملة (5,250) | B20: =ROUNDUP('التدفق الشهري'!N23/(الافتراضات!$B$22/(1+الافتراضات!$B$20)-الافتراضات!$B$22*الافتراضات!$B$21-B9*12-الافتراضات!$B$40),0)
A21: لو كل العملاء مشاريع + موارد بشرية (4,000) | B21: =ROUNDUP('التدفق الشهري'!N23/(الافتراضات!$B$24/(1+الافتراضات!$B$20)-الافتراضات!$B$24*الافتراضات!$B$21-B9*12-الافتراضات!$B$40),0)
A22: لو كل العملاء مشاريع فقط (2,500) | B22: =ROUNDUP('التدفق الشهري'!N23/(الافتراضات!$B$23/(1+الافتراضات!$B$20)-الافتراضات!$B$23*الافتراضات!$B$21-B9*12-الافتراضات!$B$40),0)
A23: لو كل العملاء موارد بشرية فقط (1,500) | B23: =ROUNDUP('التدفق الشهري'!N23/(الافتراضات!$B$25/(1+الافتراضات!$B$20)-الافتراضات!$B$25*الافتراضات!$B$21-B9*12-الافتراضات!$B$40),0)
A25: — تكلفة الاستحواذ —
A26: إجمالي التسويق + المبيعات في السنة | B26: ='التدفق الشهري'!N16+'التدفق الشهري'!N19+'التدفق الشهري'!N16*الافتراضات!$B$10 | C26: راتب المبيعات وتأميناته + التسويق
A27: تكلفة اكتساب العميل الواحد (CAC) | B27: =IF(الافتراضات!$B$54=0,0,B26/الافتراضات!$B$54) | C27: حسب خطة الاكتساب
A28: هامش العميل في السنة الأولى | B28: =B10*12
A29: فترة استرداد CAC (بالأشهر) | B29: =IF(B10<=0,0,B27/B10) | C29: الهدف: أقل من 12 شهرًا
A30: قيمة العميل على 3 سنوات ÷ CAC | B30: =IF(B27=0,0,B28*3/B27) | C30: الهدف: 3x فأكثر

Sheet السيناريوهات
A1: السيناريوهات — نتيجة السنة حسب عدد العقود المباعة
A2: الافتراض: التكاليف الثابتة كما في ورقة التدفق، وكل عقد سنوي يُدفع مقدمًا بمتوسط المزيج.
A4: البند | B4: محافظ | C4: أساسي | D4: متفائل
A5: عدد العقود المباعة في السنة (مدخل) | B5: 25 | C5: 50 | D5: 80
A6: الإيراد النقدي المقبوض | B6: =B5*الافتراضات!$B$34 | C6: =C5*الافتراضات!$B$34 | D6: =D5*الافتراضات!$B$34
A7: التكاليف الثابتة للسنة | B7: ='التدفق الشهري'!N23 | C7: ='التدفق الشهري'!N23 | D7: ='التدفق الشهري'!N23
A8: التكاليف المتغيرة (تشغيل نصف سنة في المتوسط + إعداد) | B8: =B5*(الافتراضات!$B$39*6+الافتراضات!$B$40) | C8: =C5*(الافتراضات!$B$39*6+الافتراضات!$B$40) | D8: =D5*(الافتراضات!$B$39*6+الافتراضات!$B$40)
A9: إجمالي التكاليف | B9: =B7+B8 | C9: =C7+C8 | D9: =D7+D8
A10: صافي النقد نهاية السنة | B10: =B6-B9 | C10: =C6-C9 | D10: =D6-D9
A11: الإيراد المحاسبي المكتسب (نصف العقود في المتوسط) | B11: =B6/2 | C11: =C6/2 | D11: =D6/2
A12: صافي الربح المحاسبي | B12: =B11-B9 | C12: =C11-C9 | D12: =D11-D9
A13: الإيراد الشهري المتكرر نهاية السنة (MRR) | B13: =B5*الافتراضات!$B$34/12 | C13: =C5*الافتراضات!$B$34/12 | D13: =D5*الافتراضات!$B$34/12
A14: التكلفة الثابتة في ديسمبر | B14: ='التدفق الشهري'!M23 | C14: ='التدفق الشهري'!M23 | D14: ='التدفق الشهري'!M23
A15: تغطية التكاليف الثابتة بالإيراد المتكرر | B15: =IF(B14=0,0,(B13-B5*الافتراضات!$B$39)/B14) | C15: =IF(C14=0,0,(C13-C5*الافتراضات!$B$39)/C14) | D15: =IF(D14=0,0,(D13-D5*الافتراضات!$B$39)/D14)
A17: ملاحظة: التكاليف المتغيرة هنا تقريبية (كل عميل يُخدم 6 أشهر في المتوسط). الرقم الدقيق في ورقة التدفق الشهري.
